Workbook

Sheet Tổng hợp
A1: TỔNG HỢP KẾT QUẢ KIỂM THỬ
A3: STT | B3: Tên màn hình / Chức năng | C3: Số trường hợp kiểm thử đạt (P) | D3: Số trường hợp kiểm thử không đạt (F) | E3: Số trường hợp kiểm thử đang xem xét (PE) | F3: Số trường hợp kiểm thử chưa thực hiện | G3: Tổng số trường hợp kiểm thử | H3: Tỉ lệ trường hợp kiểm thử đạt (%P) | I3: Tỉ lệ trường hợp kiểm thử không đạt (%F) | J3: Tỉ lệ trường hợp kiểm thử đã thực hiện (%Cover)
A4: 1 | B4: =UPDATE_DB_11G_TO_19C!D2 -> Nâng cấp DB HTDS_VAS 11g -> 19c | C4: =UPDATE_DB_11G_TO_19C!D4 -> 91 | D4: =UPDATE_DB_11G_TO_19C!D5 -> 0 | E4: =UPDATE_DB_11G_TO_19C!D6 -> 0 | F4: =UPDATE_DB_11G_TO_19C!D7 -> 0 | G4: =UPDATE_DB_11G_TO_19C!D8 -> 91 | H4: =C4/G4 -> 1 | I4: =D4/G4 -> 0 | J4: =(C4+D4)/G4 -> 1
A5: Total | C5: =SUM(C4:C4) -> 91 | D5: =SUM(D4:D4) -> 0 | E5: =SUM(E4:E4) -> 0 | F5: =SUM(F4:F4) -> 0 | G5: =SUM(G4:G4) -> 91 | H5: =C4/C5 -> 1 | I5: =D5/G5 -> 0 | J5: =(C5+D5)/G5 -> 1

Sheet UPDATE_DB_11G_TO_19C
C1: KỊCH BẢN KIỂM THỬ
C2: Tên màn hình / Tên chức năng | D2: Nâng cấp DB HTDS_VAS 11g -> 19c
C3: Mã trường hợp kiểm thử | D3: Up_DB
C4: Số trường hợp kiểm thử đạt (P) | D4: =COUNTIF($H$14:$H$3339,"P") -> 91
C5: Số trường hợp kiểm thử không đạt (F) | D5: =COUNTIF($H$14:$H$3339,"F") -> 0
C6: Số trường hợp kiểm thử đang xem xet (PE) | D6: =COUNTIF($H$14:$H$3339,"PE") -> 0
C7: Số trường hợp kiểm thử chưa được thực hiện | D7: =D8-D4-D5-D6 -> 0
C8: Tổng số trường hợp kiểm thử | D8: =COUNTA($D$14:$D$3339) -> 91
A10: Mã trường hợp kiểm thử | B10: Mục đích kiểm thử | C10: Các bước thực hiện | D10: Kết quả mong muốn | E10: Browser Version | H10: Kết quả hiện tại | I10: Mã lỗi | J10: Ghi chú
E11: Lần 1 | F11: Lần 2 | G11: Lần 3
B12: 3.1 Cập nhật file mã hóa tài khoản DB từ Oracle 11g sang Oracle 19c
A14: =IF(AND(D14="",D14=""),"",$D$3&"_"&ROW()-13-COUNTBLANK($D14:D$14)) -> Up_DB_1 | B14: Kiểm tra đường link thư mục chứa file cấu hình | C14: 1. Mở tomcat server test 2. Mở đường link chứa file cấu hình: /u01/app/fmra/htds_vas/htds_webapp/htds_web_deploy/tomcat_xxxx/webapps/HTDS/WEB-INF/classes/com/viettel/htds/config/datasource/ 3. Mở file và decode | D14: Hệ thống hiển thị cấu hình DB đúng với TLGP mô tả | E14: P | F14: P | G14: P | H14: P
B15: 3.2 Nâng cấp thư viện để giao tiếp với Oracle 19c
A16: =IF(AND(D16="",D16=""),"",$D$3&"_"&ROW()-13-COUNTBLANK($D$14:D16)) -> Up_DB_2 | B16: Kiểm tra đường link thư mục chứa file thư viện ojdbc7 | C16: 1. Mở tomcat server test 2. Mở đường link chứa file cấu hình: /u01/app/fmra/htds_vas/htds_webapp/htds_web_deploy/tomcat_xxxx/webapps/HTDS/WEB-INF/classes/com/viettel/htds/config/datasource/ 3. Mở file và decode | D16: Hệ thống hiển thị cấu hình DB đúng với TLGP mô tả | E16: P | F16: P | G16: P | H16: P
B17: 3.5 Cập nhật DB link
B18: Kiểm tra DB Link từ 19c -> 11g - Precondition: đã config DB Link 11g trên DB 19c (HOST = 10.207.222.182 - PORT = 1521 - SERVICE_NAME = DSVAS1)
B19: Kiểm tra kết nối cơ bản
A20: =IF(AND(D20="",D20=""),"",$D$3&"_"&ROW()-13-COUNTBLANK($D$14:D20)) -> Up_DB_3 | B20: Kiểm tra kết nối đơn giản | C20: 1. Mở script tại DB HTDS_VAS 19c 2. Nhập câu lệnh query: -- Test kết nối cơ bản SELECT * FROM dual@link_to_11g; -- Test với user cụ thể SELECT USER FROM dual@link_to_11g; | D20: Hệ thống trả về kết quả sau query: -- Test kết nối cơ bản = X -- Test với user cụ thể = DSVAS | E20: P | F20: P | G20: P | H20: P
A21: =IF(AND(D21="",D21=""),"",$D$3&"_"&ROW()-13-COUNTBLANK($D$14:D21)) -> Up_DB_4 | B21: Kiểm tra thông tin DB Link | C21: 1. Mở script tại DB HTDS_VAS 19c 2. Nhập câu lệnh query: -- Liệt kê tất cả DB Link SELECT db_link, username, host, created FROM all_db_links; -- Kiểm tra DB Link cho user hiện tại SELECT db_link, username, host FROM user_db_links; | D21: Hệ thống trả về kết quả sau query: -- Liệt kê tất cả DB Link = Toàn bộ thông DB link trên DB HTDS_VAS 19c đã đc tạo -- Kiểm tra DB Link cho user hiện tại = Toàn bộ thông DB link trên DB HTDS_VAS 19c đã đc tạo tương ứng với user | E21: P | F21: P | G21: P | H21: P
B22: Kiểm tra truy vấn dữ liệu
A23: =IF(AND(D23="",D23=""),"",$D$3&"_"&ROW()-13-COUNTBLANK($D$14:D23)) -> Up_DB_5 | B23: Kiểm tra truy vấn dữ liệu từ bảng remote | C23: 1. Mở script tại DB HTDS_VAS 19c 2. Nhập câu lệnh query: -- Test truy vấn đơn giản SELECT COUNT(*) FROM CONTRACT@link_to_11g; -- Test với điều kiện WHERE SELECT * FROM CONTRACT@link_to_11g WHERE CONTRACT_ID = 123456; | D23: Hệ thống trả về kết quả sau query: -- Test truy vấn đơn giản = số lượng dữ liệu có trong bảng CONTRACT ở DB HTDS_VAS 11g -- Test với điều kiện WHERE = hiển thị dữ liệu tương ứng với CONTRACT_ID = 123456 ở DB HTDS_VAS 11g | E23: P | F23: P | G23: P | H23: P
A24: =IF(AND(D24="",D24=""),"",$D$3&"_"&ROW()-13-COUNTBLANK($D$14:D24)) -> Up_DB_6 | B24: Kiểm tra hiệu suất truy vấn từ bảng remote | C24: 1. Mở script tại DB HTDS_VAS 19c 2. Nhập câu lệnh query: -- Đo thời gian truy vấn SELECT COUNT(*) FROM IC_REPORT_DETAIL@link_to_11g | D24: Hệ thống trả về kết quả sau query: -- Đo thời gian truy vấn: Với dữ liệu khoảng 10k mất ~ 100ms (tức khá nhanh) | E24: P | F24: P | G24: P | H24: P
B25: Kiểm tra thay đổi dữ liệu trong bảng
A26: =IF(AND(D26="",D26=""),"",$D$3&"_"&ROW()-13-COUNTBLANK($D$14:D26)) -> Up_DB_7 | B26: Kiểm tra INSERT qua DB Link | C26: 1. Mở script tại DB HTDS_VAS 19c 2. Nhập câu lệnh query: -- Test INSERT INSERT INTO DB19CTEST@link_to_11g (test_id, test_name, test_no, test_category) VALUES ('79', 'LUCKY_NUMBER', '79.79', 'Số thần tài lớn'); -- Kiểm tra dữ liệu sau khi đã insert SELECT * FROM DB19CTEST@link_to_11g WHERE TEST_ID = '79'; -- Rollback để không ảnh hưởng dữ liệu cũ ROLLBACK; | D26: Hệ thống trả về kết quả sau query: -- Test INSERT : Thông báo insert thành công 1 bản ghi -- Kiểm tra dữ liệu sau khi đã insert: Hệ thống hiển thị dữ liệu tương ứng đã insert trong bảng | E26: P | F26: P | G26: P | H26: P
A27: =IF(AND(D27="",D27=""),"",$D$3&"_"&ROW()-13-COUNTBLANK($D$14:D27)) -> Up_DB_8 | B27: Kiểm tra UPDATE qua DB Link | C27: 1. Mở script tại DB HTDS_VAS 19c 2. Nhập câu lệnh query: -- Test UPDATE UPDATE DB19CTEST@link_to_11g SET TEST_NO = '79.179' WHERE TEST_ID = '79'; -- Kiểm tra kết quả SELECT * FROM DB19CTEST@link_to_11g WHERE TEST_ID = '79'; -- Rollback để không ảnh hưởng dữ liệu cũ ROLLBACK; | D27: Hệ thống trả về kết quả sau query: -- Test UPDATE : Thông báo update thành công 1 bản ghi -- Kiểm tra dữ liệu sau khi đã update: Hệ thống hiển thị dữ liệu tương ứng đã và dữ liệu update đúng trong bảng | E27: P | F27: P | G27: P | H27: P
A28: =IF(AND(D28="",D28=""),"",$D$3&"_"&ROW()-13-COUNTBLANK($D$14:D28)) -> Up_DB_9 | B28: Kiểm tra DELETE qua DB Link | C28: 1. Mở script tại DB HTDS_VAS 19c 2. Nhập câu lệnh query: -- Test DETELE DELETE FROM DB19CTEST@link_to_11g WHERE TEST_ID = '79'; -- Kiểm tra kết quả SELECT * FROM DB19CTEST@link_to_11g WHERE TEST_ID = '79'; -- Rollback để không ảnh hưởng dữ liệu cũ ROLLBACK; | D28: Hệ thống trả về kết quả sau query: -- Test DELETE : Thông báo delete thành công 1 bản ghi -- Kiểm tra dữ liệu sau khi đã delete: Hệ thống ko hiển thị dữ liệu vì đã bị xóa trong bảng | E28: P | F28: P | G28: P | H28: P
B29: Kiểm tra thay đổi dữ liệu bảng
A30: =IF(AND(D30="",D30=""),"",$D$3&"_"&ROW()-13-COUNTBLANK($D$14:D30)) -> Up_DB_10 | B30: Kiểm tra CREATE TABLE qua DB link | C30: 1. Mở script tại DB HTDS_VAS 19c 2. Nhập câu lệnh query: -- Test CREATE bảng CREATE TABLE DB19cTEST@link_to_11g ( test_id NUMBER PRIMARY KEY, test_name VARCHAR2(100) NOT NULL, test_no NUMBER(10,2) NOT NULL, test_category VARCHAR2(50) ); -- Kiểm tra kết quả SELECT * FROM rDB19cTEST@link_to_11g; | D30: Hệ thống trả về kết quả sau query: Bảng DB19CTEST vơi các cột dữ liệu như đã khai báo Kiểm tra chi tiết về kiểu dữ liệu: Dbeaver hiển thị kiểu dữ liệu của từng cột trong bảng đúng như đã khai báo | E30: P | F30: P | G30: P | H30: P
A31: =IF(AND(D31="",D31=""),"",$D$3&"_"&ROW()-13-COUNTBLANK($D$14:D31)) -> Up_DB_11 | B31: Kiểm tra ALERT TABLE qua DB link | C31: 1. Mở script tại DB HTDS_VAS 19c 2. Nhập câu lệnh query: -- Test ALERT bảng ALTER TABLE DB19cTEST@link_to_11g ADD (description VARCHAR2(500)); -- Kiểm tra kết quả SELECT * FROM rDB19cTEST@link_to_11g; | D31: Hệ thống trả về kết quả sau query: Bảng DB19CTEST có thêm cột DESCRIPTION, các cột khác được giữ nguyên Kiểm tra chi tiết về kiểu dữ liệu: Dbeaver hiển thị kiểu dữ liệu cột DESCRIPTION đúng như đã khai báo, các cột khác ko có gì thay đổi | E31: P | F31: P | G31: P | H31: P
A32: =IF(AND(D32="",D32=""),"",$D$3&"_"&ROW()-13-COUNTBLANK($D$14:D32)) -> Up_DB_12 | B32: Kiểm tra TRUNCATE TABLE qua DB link | C32: 1. Mở script tại DB HTDS_VAS 19c - Pre: Bảng DB19cTEST đã có dữ liệu 2. Nhập câu lệnh query: -- Test TRUNCATE TRUNCATE TABLE DB19cTEST@link_to_11g; -- Kiểm tra kết quả SELECT * FROM rDB19cTEST@link_to_11g; | D32: Hệ thống trả về kết quả sau query: Bảng DB19CTEST không có dòng dữ liệu nào, cấu trúc bảng được giữ nguyên | E32: P | F32: P | G32: P | H32: P
A33: =IF(AND(D33="",D33=""),"",$D$3&"_"&ROW()-13-COUNTBLANK($D$14:D33)) -> Up_DB_13 | B33: Kiểm tra DROP TABLE qua DB link | C33: 1. Mở script tại DB HTDS_VAS 19c 2. Nhập câu lệnh query: -- Test DROP DROP TABLE DB19cTEST@link_to_11g; -- Kiểm tra kết quả SELECT * FROM rDB19cTEST@link_to_11g; | D33: Hệ thống trả về kết quả sau query: Báo lỗi không có bảng DB19CTEST không tồn tại ~ xóa hoàn toàn bảng khỏi DB | E33: P | F33: P | G33: P | H33: P
B34: Kiểm tra các kịch bản sẽ báo lỗi
A35: =IF(AND(D35="",D35=""),"",$D$3&"_"&ROW()-13-COUNTBLANK($D$14:D35)) -> Up_DB_14 | B35: Kiểm tra DB Link không tồn tại | C35: 1. Mở script tại DB HTDS_VAS 19c 2. Nhập câu lệnh query: -- Test với DB Link không tồn tại SELECT * FROM dual@abc_123_abc_456; | D35: Hệ thống trả về kết quả sau query: Báo lỗi không tồn tại DB link abc_123_abc_456 | E35: P | F35: P | G35: P | H35: P
A36: =IF(AND(D36="",D36=""),"",$D$3&"_"&ROW()-13-COUNTBLANK($D$14:D36)) -> Up_DB_15 | B36: Kiểm tra table trong DB Link không tồn tại | C36: 1. Mở script tại DB HTDS_VAS 19c 2. Nhập câu lệnh query: -- Test với table không tồn tại SELECT * FROM 112233abcdef@link_to_11g; | D36: Hệ thống trả về kết quả sau query: Báo lỗi không tồn tại bảng 112233abcdef | E36: P | F36: P | G36: P | H36: P
A37: =IF(AND(D37="",D37=""),"",$D$3&"_"&ROW()-13-COUNTBLANK($D$14:D37)) -> Up_DB_16 | B37: Kiểm tra table trong DB Link không được cấp quyền truy cập | C37: 1. Mở script tại DB HTDS_VAS 19c 2. Nhập câu lệnh query: -- Test với table không tồn tại SELECT * FROM …...@link_to_11g; | D37: Hệ thống trả về kết quả sau query: Báo lỗi không có quyền truy cập bảng….. | E37: P | F37: P | G37: P | H37: P
B38: Kiểm tra đồng bộ dữ liệu
A39: =IF(AND(D39="",D39=""),"",$D$3&"_"&ROW()-13-COUNTBLANK($D$14:D39)) -> Up_DB_17 | B39: Kiểm tra số lượng bản ghi đang tồn tại | C39: 1. Mở script tại DB HTDS_VAS 19c 2. Nhập câu lệnh query: SELECT COUNT(*) as count FROM CONTRACT UNION ALL SELECT COUNT(*) as count FROM CONTRACT@link_to_11g; | D39: Hệ thống trả về 2 kết quả và so sánh - Nếu DB mới build và mới đồng bộ mà: + DB gốc > DB link -> mất dự liệu khi đồng bộ + DB gốc = DB link: Dữ liệu đc đồng bộ hoàn toàn + DB gốc < DB link -> dự liệu bị xử lý sai lệch/thừa khi đồng bộ - Nếu DB đã build lâu và đã thao tác tác động tới DB: 2 kết quả bình thường, không phản ánh được đúng sai của tiến trình đồng bộ | E39: P | F39: P | G39: P | H39: P
A40: =IF(AND(D40="",D40=""),"",$D$3&"_"&ROW()-13-COUNTBLANK($D$14:D40)) -> Up_DB_18 | B40: Kiểm tra và so sánh dữ liệu cụ thể | C40: 1. Mở script tại DB HTDS_VAS 19c 2. Nhập câu lệnh query: SELECT c.*, r.* FROM CONTRACT c FULL OUTER JOIN CONTRACT@link_to_11g r ON c.CONTRACT_ID = r.CONTRACT_ID; | D40: Hệ thống trả về kết quả sau khi query: Trả về toàn bộ dữ liệu phù hợp với điều kiện join, chọn bất 1 dòng dữ liệu ko bị sửa rồi (hoặc ngay sau khi đồng bộ) thì data trả về từ bảng gốc và bảng remote giống nhau hoàn toàn | E40: P | F40: P | G40: P | H40: P
B41: Kiểm tra DB Link từ 11g -> 19c - Precondition: đã config DB Link 19c trên DB 11g (HOST = 10.207.222.143 - PORT = 9000 - SERVICE_NAME = DSVAS1)
B42: Kiểm tra kết nối cơ bản
...
